Workbook

Sheet Summary
A1: SAP Lens validation checklist
A2: Generated from docs/validation/validation-items.csv. Status and Manual approval are recorded by people; automated test evidence is listed separately on the Items sheet. Nothing is approved automatically.
A3: Completion = Passed, Failed and Needs improvement over applicable items. Approved = manually approved over applicable items. Defects and Future Improvements are snapshots taken when the workbook was generated.
A5: Area | B5: Items | C5: Not tested | D5: Passed | E5: Failed | F5: Needs improvement | G5: Blocked | H5: Not applicable | I5: Manual approved | J5: Manual pending | K5: Completion | L5: Approved
A6: Dashboard | B6: =COUNTIFS(Items!$B$2:$B$225,$A6) -> 9 | C6: =COUNTIFS(Items!$B$2:$B$225,$A6,Items!$F$2:$F$225,C$5) -> 9 | D6: =COUNTIFS(Items!$B$2:$B$225,$A6,Items!$F$2:$F$225,D$5) -> 0 | E6: =COUNTIFS(Items!$B$2:$B$225,$A6,Items!$F$2:$F$225,E$5) -> 0 | F6: =COUNTIFS(Items!$B$2:$B$225,$A6,Items!$F$2:$F$225,F$5) -> 0 | G6: =COUNTIFS(Items!$B$2:$B$225,$A6,Items!$F$2:$F$225,G$5) -> 0 | H6: =COUNTIFS(Items!$B$2:$B$225,$A6,Items!$F$2:$F$225,H$5) -> 0 | I6: =COUNTIFS(Items!$B$2:$B$225,$A6,Items!$G$2:$G$225,"Approved") -> 0 | J6: =COUNTIFS(Items!$B$2:$B$225,$A6,Items!$G$2:$G$225,"Pending") -> 9 | K6: =IF(B6-G6=0,0,(D6+E6+F6)/(B6-G6)) -> 0 | L6: =IF(B6-G6=0,0,H6/(B6-G6)) -> 0
A7: Role Lookup | B7: =COUNTIFS(Items!$B$2:$B$225,$A7) -> 10 | C7: =COUNTIFS(Items!$B$2:$B$225,$A7,Items!$F$2:$F$225,C$5) -> 10 | D7: =COUNTIFS(Items!$B$2:$B$225,$A7,Items!$F$2:$F$225,D$5) -> 0 | E7: =COUNTIFS(Items!$B$2:$B$225,$A7,Items!$F$2:$F$225,E$5) -> 0 | F7: =COUNTIFS(Items!$B$2:$B$225,$A7,Items!$F$2:$F$225,F$5) -> 0 | G7: =COUNTIFS(Items!$B$2:$B$225,$A7,Items!$F$2:$F$225,G$5) -> 0 | H7: =COUNTIFS(Items!$B$2:$B$225,$A7,Items!$F$2:$F$225,H$5) -> 0 | I7: =COUNTIFS(Items!$B$2:$B$225,$A7,Items!$G$2:$G$225,"Approved") -> 0 | J7: =COUNTIFS(Items!$B$2:$B$225,$A7,Items!$G$2:$G$225,"Pending") -> 10 | K7: =IF(B7-G7=0,0,(D7+E7+F7)/(B7-G7)) -> 0 | L7: =IF(B7-G7=0,0,H7/(B7-G7)) -> 0
A8: Access Package | B8: =COUNTIFS(Items!$B$2:$B$225,$A8) -> 9 | C8: =COUNTIFS(Items!$B$2:$B$225,$A8,Items!$F$2:$F$225,C$5) -> 8 | D8: =COUNTIFS(Items!$B$2:$B$225,$A8,Items!$F$2:$F$225,D$5) -> 0 | E8: =COUNTIFS(Items!$B$2:$B$225,$A8,Items!$F$2:$F$225,E$5) -> 0 | F8: =COUNTIFS(Items!$B$2:$B$225,$A8,Items!$F$2:$F$225,F$5) -> 1 | G8: =COUNTIFS(Items!$B$2:$B$225,$A8,Items!$F$2:$F$225,G$5) -> 0 | H8: =COUNTIFS(Items!$B$2:$B$225,$A8,Items!$F$2:$F$225,H$5) -> 0 | I8: =COUNTIFS(Items!$B$2:$B$225,$A8,Items!$G$2:$G$225,"Approved") -> 0 | J8: =COUNTIFS(Items!$B$2:$B$225,$A8,Items!$G$2:$G$225,"Pending") -> 9 | K8: =IF(B8-G8=0,0,(D8+E8+F8)/(B8-G8)) -> 0.111111 | L8: =IF(B8-G8=0,0,H8/(B8-G8)) -> 0
A9: User Directory | B9: =COUNTIFS(Items!$B$2:$B$225,$A9) -> 9 | C9: =COUNTIFS(Items!$B$2:$B$225,$A9,Items!$F$2:$F$225,C$5) -> 9 | D9: =COUNTIFS(Items!$B$2:$B$225,$A9,Items!$F$2:$F$225,D$5) -> 0 | E9: =COUNTIFS(Items!$B$2:$B$225,$A9,Items!$F$2:$F$225,E$5) -> 0 | F9: =COUNTIFS(Items!$B$2:$B$225,$A9,Items!$F$2:$F$225,F$5) -> 0 | G9: =COUNTIFS(Items!$B$2:$B$225,$A9,Items!$F$2:$F$225,G$5) -> 0 | H9: =COUNTIFS(Items!$B$2:$B$225,$A9,Items!$F$2:$F$225,H$5) -> 0 | I9: =COUNTIFS(Items!$B$2:$B$225,$A9,Items!$G$2:$G$225,"Approved") -> 0 | J9: =COUNTIFS(Items!$B$2:$B$225,$A9,Items!$G$2:$G$225,"Pending") -> 9 | K9: =IF(B9-G9=0,0,(D9+E9+F9)/(B9-G9)) -> 0 | L9: =IF(B9-G9=0,0,H9/(B9-G9)) -> 0
A10: Account Review | B10: =COUNTIFS(Items!$B$2:$B$225,$A10) -> 9 | C10: =COUNTIFS(Items!$B$2:$B$225,$A10,Items!$F$2:$F$225,C$5) -> 9 | D10: =COUNTIFS(Items!$B$2:$B$225,$A10,Items!$F$2:$F$225,D$5) -> 0 | E10: =COUNTIFS(Items!$B$2:$B$225,$A10,Items!$F$2:$F$225,E$5) -> 0 | F10: =COUNTIFS(Items!$B$2:$B$225,$A10,Items!$F$2:$F$225,F$5) -> 0 | G10: =COUNTIFS(Items!$B$2:$B$225,$A10,Items!$F$2:$F$225,G$5) -> 0 | H10: =COUNTIFS(Items!$B$2:$B$225,$A10,Items!$F$2:$F$225,H$5) -> 0 | I10: =COUNTIFS(Items!$B$2:$B$225,$A10,Items!$G$2:$G$225,"Approved") -> 0 | J10: =COUNTIFS(Items!$B$2:$B$225,$A10,Items!$G$2:$G$225,"Pending") -> 9 | K10: =IF(B10-G10=0,0,(D10+E10+F10)/(B10-G10)) -> 0 | L10: =IF(B10-G10=0,0,H10/(B10-G10)) -> 0
A11: Compare Users | B11: =COUNTIFS(Items!$B$2:$B$225,$A11) -> 5 | C11: =COUNTIFS(Items!$B$2:$B$225,$A11,Items!$F$2:$F$225,C$5) -> 5 | D11: =COUNTIFS(Items!$B$2:$B$225,$A11,Items!$F$2:$F$225,D$5) -> 0 | E11: =COUNTIFS(Items!$B$2:$B$225,$A11,Items!$F$2:$F$225,E$5) -> 0 | F11: =COUNTIFS(Items!$B$2:$B$225,$A11,Items!$F$2:$F$225,F$5) -> 0 | G11: =COUNTIFS(Items!$B$2:$B$225,$A11,Items!$F$2:$F$225,G$5) -> 0 | H11: =COUNTIFS(Items!$B$2:$B$225,$A11,Items!$F$2:$F$225,H$5) -> 0 | I11: =COUNTIFS(Items!$B$2:$B$225,$A11,Items!$G$2:$G$225,"Approved") -> 0 | J11: =COUNTIFS(Items!$B$2:$B$225,$A11,Items!$G$2:$G$225,"Pending") -> 5 | K11: =IF(B11-G11=0,0,(D11+E11+F11)/(B11-G11)) -> 0 | L11: =IF(B11-G11=0,0,H11/(B11-G11)) -> 0
A12: Release Roles | B12: =COUNTIFS(Items!$B$2:$B$225,$A12) -> 5 | C12: =COUNTIFS(Items!$B$2:$B$225,$A12,Items!$F$2:$F$225,C$5) -> 5 | D12: =COUNTIFS(Items!$B$2:$B$225,$A12,Items!$F$2:$F$225,D$5) -> 0 | E12: =COUNTIFS(Items!$B$2:$B$225,$A12,Items!$F$2:$F$225,E$5) -> 0 | F12: =COUNTIFS(Items!$B$2:$B$225,$A12,Items!$F$2:$F$225,F$5) -> 0 | G12: =COUNTIFS(Items!$B$2:$B$225,$A12,Items!$F$2:$F$225,G$5) -> 0 | H12: =COUNTIFS(Items!$B$2:$B$225,$A12,Items!$F$2:$F$225,H$5) -> 0 | I12: =COUNTIFS(Items!$B$2:$B$225,$A12,Items!$G$2:$G$225,"Approved") -> 0 | J12: =COUNTIFS(Items!$B$2:$B$225,$A12,Items!$G$2:$G$225,"Pending") -> 5 | K12: =IF(B12-G12=0,0,(D12+E12+F12)/(B12-G12)) -> 0 | L12: =IF(B12-G12=0,0,H12/(B12-G12)) -> 0
A13: SoD Overview | B13: =COUNTIFS(Items!$B$2:$B$225,$A13) -> 9 | C13: =COUNTIFS(Items!$B$2:$B$225,$A13,Items!$F$2:$F$225,C$5) -> 9 | D13: =COUNTIFS(Items!$B$2:$B$225,$A13,Items!$F$2:$F$225,D$5) -> 0 | E13: =COUNTIFS(Items!$B$2:$B$225,$A13,Items!$F$2:$F$225,E$5) -> 0 | F13: =COUNTIFS(Items!$B$2:$B$225,$A13,Items!$F$2:$F$225,F$5) -> 0 | G13: =COUNTIFS(Items!$B$2:$B$225,$A13,Items!$F$2:$F$225,G$5) -> 0 | H13: =COUNTIFS(Items!$B$2:$B$225,$A13,Items!$F$2:$F$225,H$5) -> 0 | I13: =COUNTIFS(Items!$B$2:$B$225,$A13,Items!$G$2:$G$225,"Approved") -> 0 | J13: =COUNTIFS(Items!$B$2:$B$225,$A13,Items!$G$2:$G$225,"Pending") -> 9 | K13: =IF(B13-G13=0,0,(D13+E13+F13)/(B13-G13)) -> 0 | L13: =IF(B13-G13=0,0,H13/(B13-G13)) -> 0
A14: Risk Matrix | B14: =COUNTIFS(Items!$B$2:$B$225,$A14) -> 17 | C14: =COUNTIFS(Items!$B$2:$B$225,$A14,Items!$F$2:$F$225,C$5) -> 17 | D14: =COUNTIFS(Items!$B$2:$B$225,$A14,Items!$F$2:$F$225,D$5) -> 0 | E14: =COUNTIFS(Items!$B$2:$B$225,$A14,Items!$F$2:$F$225,E$5) -> 0 | F14: =COUNTIFS(Items!$B$2:$B$225,$A14,Items!$F$2:$F$225,F$5) -> 0 | G14: =COUNTIFS(Items!$B$2:$B$225,$A14,Items!$F$2:$F$225,G$5) -> 0 | H14: =COUNTIFS(Items!$B$2:$B$225,$A14,Items!$F$2:$F$225,H$5) -> 0 | I14: =COUNTIFS(Items!$B$2:$B$225,$A14,Items!$G$2:$G$225,"Approved") -> 0 | J14: =COUNTIFS(Items!$B$2:$B$225,$A14,Items!$G$2:$G$225,"Pending") -> 17 | K14: =IF(B14-G14=0,0,(D14+E14+F14)/(B14-G14)) -> 0 | L14: =IF(B14-G14=0,0,H14/(B14-G14)) -> 0
A15: Activity Matrix | B15: =COUNTIFS(Items!$B$2:$B$225,$A15) -> 4 | C15: =COUNTIFS(Items!$B$2:$B$225,$A15,Items!$F$2:$F$225,C$5) -> 4 | D15: =COUNTIFS(Items!$B$2:$B$225,$A15,Items!$F$2:$F$225,D$5) -> 0 | E15: =COUNTIFS(Items!$B$2:$B$225,$A15,Items!$F$2:$F$225,E$5) -> 0 | F15: =COUNTIFS(Items!$B$2:$B$225,$A15,Items!$F$2:$F$225,F$5) -> 0 | G15: =COUNTIFS(Items!$B$2:$B$225,$A15,Items!$F$2:$F$225,G$5) -> 0 | H15: =COUNTIFS(Items!$B$2:$B$225,$A15,Items!$F$2:$F$225,H$5) -> 0 | I15: =COUNTIFS(Items!$B$2:$B$225,$A15,Items!$G$2:$G$225,"Approved") -> 0 | J15: =COUNTIFS(Items!$B$2:$B$225,$A15,Items!$G$2:$G$225,"Pending") -> 4 | K15: =IF(B15-G15=0,0,(D15+E15+F15)/(B15-G15)) -> 0 | L15: =IF(B15-G15=0,0,H15/(B15-G15)) -> 0
A16: Access Explorer | B16: =COUNTIFS(Items!$B$2:$B$225,$A16) -> 9 | C16: =COUNTIFS(Items!$B$2:$B$225,$A16,Items!$F$2:$F$225,C$5) -> 9 | D16: =COUNTIFS(Items!$B$2:$B$225,$A16,Items!$F$2:$F$225,D$5) -> 0 | E16: =COUNTIFS(Items!$B$2:$B$225,$A16,Items!$F$2:$F$225,E$5) -> 0 | F16: =COUNTIFS(Items!$B$2:$B$225,$A16,Items!$F$2:$F$225,F$5) -> 0 | G16: =COUNTIFS(Items!$B$2:$B$225,$A16,Items!$F$2:$F$225,G$5) -> 0 | H16: =COUNTIFS(Items!$B$2:$B$225,$A16,Items!$F$2:$F$225,H$5) -> 0 | I16: =COUNTIFS(Items!$B$2:$B$225,$A16,Items!$G$2:$G$225,"Approved") -> 0 | J16: =COUNTIFS(Items!$B$2:$B$225,$A16,Items!$G$2:$G$225,"Pending") -> 9 | K16: =IF(B16-G16=0,0,(D16+E16+F16)/(B16-G16)) -> 0 | L16: =IF(B16-G16=0,0,H16/(B16-G16)) -> 0
A17: SoD Reviews | B17: =COUNTIFS(Items!$B$2:$B$225,$A17) -> 15 | C17: =COUNTIFS(Items!$B$2:$B$225,$A17,Items!$F$2:$F$225,C$5) -> 14 | D17: =COUNTIFS(Items!$B$2:$B$225,$A17,Items!$F$2:$F$225,D$5) -> 0 | E17: =COUNTIFS(Items!$B$2:$B$225,$A17,Items!$F$2:$F$225,E$5) -> 0 | F17: =COUNTIFS(Items!$B$2:$B$225,$A17,Items!$F$2:$F$225,F$5) -> 1 | G17: =COUNTIFS(Items!$B$2:$B$225,$A17,Items!$F$2:$F$225,G$5) -> 0 | H17: =COUNTIFS(Items!$B$2:$B$225,$A17,Items!$F$2:$F$225,H$5) -> 0 | I17: =COUNTIFS(Items!$B$2:$B$225,$A17,Items!$G$2:$G$225,"Approved") -> 0 | J17: =COUNTIFS(Items!$B$2:$B$225,$A17,Items!$G$2:$G$225,"Pending") -> 15 | K17: =IF(B17-G17=0,0,(D17+E17+F17)/(B17-G17)) -> 0.066667 | L17: =IF(B17-G17=0,0,H17/(B17-G17)) -> 0
... A27: Security and Data Integrity | B27: =COUNTIFS(Items!$B$2:$B$225,$A27) -> 14 | C27: =COUNTIFS(Items!$B$2:$B$225,$A27,Items!$F$2:$F$225,C$5) -> 14 | D27: =COUNTIFS(Items!$B$2:$B$225,$A27,Items!$F$2:$F$225,D$5) -> 0 | E27: =COUNTIFS(Items!$B$2:$B$225,$A27,Items!$F$2:$F$225,E$5) -> 0 | F27: =COUNTIFS(Items!$B$2:$B$225,$A27,Items!$F$2:$F$225,F$5) -> 0 | G27: =COUNTIFS(Items!$B$2:$B$225,$A27,Items!$F$2:$F$225,G$5) -> 0 | H27: =COUNTIFS(Items!$B$2:$B$225,$A27,Items!$F$2:$F$225,H$5) -> 0 | I27: =COUNTIFS(Items!$B$2:$B$225,$A27,Items!$G$2:$G$225,"Approved") -> 0 | J27: =COUNTIFS(Items!$B$2:$B$225,$A27,Items!$G$2:$G$225,"Pending") -> 14 | K27: =IF(B27-G27=0,0,(D27+E27+F27)/(B27-G27)) -> 0 | L27: =IF(B27-G27=0,0,H27/(B27-G27)) -> 0
A28: All areas | B28: =SUM(B6:B27) -> 224 | C28: =SUM(C6:C27) -> 218 | D28: =SUM(D6:D27) -> 0 | E28: =SUM(E6:E27) -> 0 | F28: =SUM(F6:F27) -> 3 | G28: =SUM(G6:G27) -> 3 | H28: =SUM(H6:H27) -> 0 | I28: =SUM(I6:I27) -> 0 | J28: =SUM(J6:J27) -> 224 | K28: =IF(B28-G28=0,0,(D28+E28+F28)/(B28-G28)) -> 0.013393 | L28: =IF(B28-G28=0,0,H28/(B28-G28)) -> 0
A30: Outstanding | B30: Count
A31: Failed items | B31: =COUNTIFS(Items!$F$2:$F$225,"Failed") -> 0
A32: Items needing improvement | B32: =COUNTIFS(Items!$F$2:$F$225,"Needs improvement") -> 3
A33: Blocked items | B33: =COUNTIFS(Items!$F$2:$F$225,"Blocked") -> 3
A34: Items linked to an open finding | B34: =COUNTIFS(Items!$L$2:$L$225,"<>",Items!$F$2:$F$225,"<>Passed") -> 11
A35: Items with automated test evidence | B35: =COUNTIFS(Items!$H$2:$H$225,"<>") -> 83

Sheet Items
A1: ID | B1: Area | C1: Page/component | D1: Validation criterion | E1: Priority | F1: Status | G1: Manual approval | H1: Automated test evidence | I1: Last validated date | J1: Build/commit | K1: Notes | L1: Linked issue or finding | M1: Potential future improvement | N1: Manual validation steps | O1: Known limitations | P1: Implementation reference | Q1: Implementation status | R1: Classification | S1: Retest status
A2: DASH-001 | B2: Dashboard | C2: Dashboard › Access & Risk card | D2: SAP users, role assignment records and risk figures match the loaded data and open the matching filtered view. | E2: Not set | F2: Not tested | G2: Pending | P2: docs/features/DASHBOARD.md; frontend/tests/dashboard-user-transactions.spec.ts | Q2: Not assessed | R2: Unclassified | S2: Not started
A3: DASH-002 | B3: Dashboard | C3: Dashboard › Review Progress card | D3: Completed, not yet reviewed and outdated reviews with the share reviewed; no invented trends. | E3: Not set | F3: Not tested | G3: Pending | P3: docs/features/DASHBOARD.md; frontend/tests/refinement-r2.spec.ts | Q3: Not assessed | R3: Unclassified | S3: Not started
A4: DASH-003 | B4: Dashboard | C4: Dashboard › Directory & Data Health card | D4: Match percentage uses the central thresholds; matched, missing and ambiguous partition the SAP users; position changes are independent. | E4: Not set | F4: Not tested | G4: Pending | P4: docs/features/DASHBOARD.md; frontend/tests/refinement-r2.spec.ts | Q4: Not assessed | R4: Unclassified | S4: Not started
A5: DASH-004 | B5: Dashboard | C5: Dashboard › Segregation of Duties card | D5: Distinct loading, failed, unavailable and ready states; counts open the matching SoD view. | E5: Not set | F5: Not tested | G5: Pending | P5: docs/features/DASHBOARD.md; frontend/tests/sod-dashboard-startup.spec.ts, frontend/tests/sod-overview-heatmap.spec.ts | Q5: Not assessed | R5: Unclassified | S5: Not started
A6: DASH-005 | B6: Dashboard | C6: Dashboard › Data Sources & Configuration | D6: Source cards report Ready, Loading, Refreshing and Failed honestly and link to their settings. | E6: Not set | F6: Not tested | G6: Pending | P6: docs/features/DASHBOARD.md; frontend/tests/startup-reliability.spec.ts | Q6: Not assessed | R6: Unclassified | S6: Not started
A7: DASH-006 | B7: Dashboard | C7: Dashboard › Assignment Distribution | D7: Five ranges (0-5, 6-10, 11-20, 21-30, 31+) over every SAP user with shares and a drilldown to User Access. | E7: Not set | F7: Not tested | G7: Pending | P7: docs/features/DASHBOARD.md; frontend/tests/refinement-round2.spec.ts | Q7: Not assessed | R7: Unclassified | S7: Not started
A8: DASH-007 | B8: Dashboard | C8: Dashboard › Role Distribution | D8: Five areas are listed and the rest open in a dialog; the grid never stretches. | E8: Not set | F8: Not tested | G8: Pending | P8: docs/features/DASHBOARD.md; frontend/tests/refinement-r2.spec.ts | Q8: Not assessed | R8: Unclassified | S8: Not started
A9: DASH-008 | B9: Dashboard | C9: Dashboard › Navigation and Back | D9: KPI and row links open filtered views and browser Back restores the Dashboard. | E9: Not set | F9: Not tested | G9: Pending | P9: docs/features/DASHBOARD.md; frontend/tests/dashboard-user-transactions.spec.ts | Q9: Not assessed | R9: Unclassified | S9: Not started
A10: DASH-009 | B10: Dashboard | C10: Dashboard › Layout | D10: Three columns on wide screens, two on tablet and one on mobile without stretched cards. | E10: Not set | F10: Not tested | G10: Pending | P10: docs/features/DASHBOARD.md; frontend/tests/refinement-completion.spec.ts | Q10: Not assessed | R10: Unclassified | S10: Not started
A11: ROLE-001 | B11: Role Lookup | C11: Role Lookup › Search | D11: Search by role name and description returns the expected roles and keeps results stable. | E11: Not set | F11: Not tested | G11: Pending | P11: docs/features/ROLE_LOOKUP.md; frontend/tests/live-filters-polish.spec.ts | Q11: Not assessed | R11: Unclassified | S11: Not started
A12: ROLE-002 | B12: Role Lookup | C12: Role Lookup › SAP area filters | D12: Module filters narrow roles by catalogue evidence only and never infer a module. | E12: Not set | F12: Not tested | G12: Pending | P12: docs/features/ROLE_LOOKUP.md; frontend/tests/consolidated-role-ui.spec.ts | Q12: Not assessed | R12: Unclassified | S12: Not started
A13: ROLE-003 | B13: Role Lookup | C13: Role Lookup › Transaction filter | D13: Include and exclude transaction codes match exactly and combine with the other filters. | E13: Not set | F13: Not tested | G13: Pending | P13: docs/features/ROLE_LOOKUP.md; frontend/tests/transaction-filter.spec.ts | Q13: Not assessed | R13: Unclassified | S13: Not started
... A18: ROLE-008 | B18: Role Lookup | C18: Role Lookup › Saved filters | D18: Role Lookup filters save, load, rename and delete. | E18: Not set | F18: Not tested | G18: Pending | P18: docs/features/SAVED_FILTERS.md; frontend/tests/saved-filter-migration.spec.ts | Q18: Not assessed | R18: Unclassified | S18: Not started
A19: R8-01 | B19: Role Lookup | C19: Role Lookup › Card header (module badge) | D19: The module pill, description and actions share one centered line of one height for every card; the description ends in an ellipsis when it does not fit (see R81-10); correct in both themes and at 320, 375, 800, 1280 and 1600 px. | E19: Medium | F19: Not tested | G19: Pending | H19: frontend/tests/r8-ui-polish.spec.ts | K19: Root cause: a later override centred the badge against the whole multiline description and let the actions wrap below it. Fixed with first-baseline alignment (R8 phase 1). Superseded in R8 addendum: the header no longer wraps; the full description is available on demand (R81-10). | N19: Look at long and short descriptions in both themes at 375, 800, 1280 and 1600 px. | P19: frontend/src/styles/components.css; frontend/src/components/Shared/RoleEntry.tsx | Q19: Implemented | R19: Unclassified | S19: Not started
A20: PKG-001 | B20: Access Package | C20: Role Lookup and Release Roles › Add to package | D20: Roles can be added and removed from role cards, details and Release Roles; the package bar counts them. | E20: Not set | F20: Not tested | G20: Pending | P20: docs/features/ROLE_LOOKUP.md; frontend/tests/access-package.spec.ts | Q20: Not assessed | R20: Unclassified | S20: Not started
A21: PKG-002 | B21: Access Package | C21: Access Package panel › Suffix configuration | D21: Package default suffix and role-specific suffixes generate the proposed names; exact roles keep their name. | E21: Not set | F21: Not tested | G21: Pending | P21: docs/features/ROLE_LOOKUP.md; frontend/tests/access-package-r2.spec.ts | Q21: Not assessed | R21: Unclassified | S21: Not started
A22: PKG-003 | B22: Access Package | C22: Access Package panel › Suffix eligibility | D22: Only trailing-wildcard patterns or roles ending in a detected organizational suffix take a suffix. | E22: Not set | F22: Not tested | G22: Pending | P22: docs/features/ROLE_LOOKUP.md; frontend/tests/access-package-r2.spec.ts | Q22: Not assessed | R22: Unclassified | S22: Not started
A23: PKG-004 | B23: Access Package | C23: Access Package panel › Validation statuses | D23: Confirmed needs the exact name in imported roles or assignments; wildcard matches are Pattern match; unsupported valid names are Needs attention; invalid names never export. | E23: Not set | F23: Not tested | G23: Pending | P23: docs/features/ROLE_LOOKUP.md; frontend/tests/access-package.spec.ts, frontend/tests/access-package-r2.spec.ts | Q23: Not assessed | R23: Unclassified | S23: Not started
A24: PKG-005 | B24: Access Package | C24: Access Package panel › Clear selection and Clear package | D24: Clear selection clears only selected roles; Clear package confirms and clears only the package; neither looks enabled without a target. | E24: Not set | F24: Not tested | G24: Pending | P24: docs/features/ROLE_LOOKUP.md; frontend/tests/access-package-r2.spec.ts | Q24: Not assessed | R24: Unclassified | S24: Not started
A25: PKG-006 | B25: Access Package | C25: Access Package panel › Copy and CSV export | D25: Copy all names and Export CSV include the Validation column and respect the package contents. | E25: Not set | F25: Not tested | G25: Pending | P25: docs/features/ROLE_LOOKUP.md; frontend/tests/access-package.spec.ts | Q25: Not assessed | R25: Unclassified | S25: Not started
A26: PKG-007 | B26: Access Package | C26: Access Package panel › Package rows | D26: Rows show badge, description, one codeblock, suffix field and status compactly at 375 px. | E26: Not set | F26: Not tested | G26: Pending | P26: docs/features/ROLE_LOOKUP.md; frontend/tests/access-package-r2.spec.ts | Q26: Not assessed | R26: Unclassified | S26: Not started
A27: PKG-008 | B27: Access Package | C27: Access Package panel › Long role names | D27: Long generated names stay on one complete line (font scales in the narrow panel), never wrap or scroll, and copy exactly. | E27: Not set | F27: Not tested | G27: Pending | P27: docs/features/ROLE_LOOKUP.md; frontend/tests/access-package-r2.spec.ts | Q27: Not assessed | R27: Unclassified | S27: Not started
A28: PKG-009 | B28: Access Package | C28: Role Lookup and Release Roles › Floating bars on narrow screens | D28: The package and selection bars together leave most of a 375 px viewport usable. | E28: Low | F28: Needs improvement | G28: Pending | K28: Round 4 visual QA at 375 px: the package bar wraps its two buttons onto separate lines and, with the selection bar, stacks to roughly a quarter of the viewport height. | P28: frontend/src/components/Shared/AccessPackageBar.tsx; docs/features/ROLE_LOOKUP.md | Q28: Not assessed | R28: Improvement opportunity | S28: Not started
A29: UA-001 | B29: User Directory | C29: User directory › User list and search | D29: SAP users list with group, roles and filters; search matches username and name. | E29: Not set | F29: Not tested | G29: Pending | P29: docs/features/USER_ACCESS.md; frontend/tests/investigation-ux.spec.ts | Q29: Not assessed | R29: Unclassified | S29: Not started
A30: UA-002 | B30: User Directory | C30: User detail › Assignments | D30: Assignments show role, validity, catalogue evidence and match status with source evidence. | E30: Not set | F30: Not tested | G30: Pending | P30: docs/features/USER_ACCESS.md; frontend/tests/access-investigation.spec.ts | Q30: Not assessed | R30: Unclassified | S30: Not started
A31: UA-003 | B31: User Directory | C31: User directory › Missing roles filter | D31: ANY and ALL semantics for missing roles behave as documented. | E31: Not set | F31: Not tested | G31: Pending | P31: docs/features/USER_ACCESS.md; frontend/tests/investigation-tools.spec.ts | Q31: Not assessed | R31: Unclassified | S31: Not started
A32: UA-004 | B32: User Directory | C32: User directory › Reverse transaction filter | D32: Users who have or lack transactions are found by exact transaction evidence. | E32: Not set | F32: Not tested | G32: Pending | P32: docs/features/USER_ACCESS.md; frontend/tests/transaction-filter.spec.ts | Q32: Not assessed | R32: Unclassified | S32: Not started
A33: UA-005 | B33: User Directory | C33: User directory › Assignment ranges | D33: Assignment range filter matches the Dashboard distribution. | E33: Not set | F33: Not tested | G33: Pending | P33: docs/features/USER_ACCESS.md; frontend/tests/refinement-round2.spec.ts | Q33: Not assessed | R33: Unclassified | S33: Not started
A34: UA-006 | B34: User Directory | C34: User detail › Expired and future assignments | D34: Expired, future and unknown validity are separated from active assignments. | E34: Not set | F34: Not tested | G34: Pending | P34: docs/features/USER_ACCESS.md; frontend/tests/access-investigation.spec.ts | Q34: Not assessed | R34: Unclassified | S34: Not started
A35: UA-007 | B35: User Directory | C35: User directory › Export | D35: CSV export respects the active filters and includes the expected evidence columns. | E35: Not set | F35: Not tested | G35: Pending | P35: docs/features/USER_ACCESS.md; frontend/tests/user-role-export.spec.ts | Q35: Not assessed | R35: Unclassified | S35: Not started
A36: UA-008 | B36: User Directory | C36: User detail › Return to previous user | D36: The manager card offers Return to previous user only after navigating from another user. | E36: Not set | F36: Not tested | G36: Pending | P36: docs/architecture/NAVIGATION.md; frontend/tests/employee-directory.spec.ts | Q36: Not assessed | R36: Unclassified | S36: Not started
A37: UA-009 | B37: User Directory | C37: User detail › Employee enrichment | D37: Manager relationships and directory fields appear only when the Employee Directory is enabled and matched. | E37: Not set | F37: Not tested | G37: Pending | P37: docs/data/EMPLOYEE_DIRECTORY.md; frontend/tests/employee-directory.spec.ts | Q37: Not assessed | R37: Unclassified | S37: Not started
A38: AR-001 | B38: Account Review | C38: Account Review › Progress section | D38: One compact panel (about one third of the width) shows the completion percentage, N of M SAP users reviewed, a visible progress bar and clickable completed and pending counts; outdated reviews count as pending. | E38: Not set | F38: Not tested | G38: Pending | P38: docs/features/ACCOUNT_REVIEW.md; frontend/tests/account-review-refinement.spec.ts | Q38: Not assessed | R38: Unclassified | S38: Not started
A39: AR-002 | B39: Account Review | C39: Account Review › Action KPIs | D39: The Review attention panel (about two thirds of the width, two columns, icons, right-aligned values) lists accounts requiring review, missing or ambiguous directory matches, position changes and outdated reviews plus a compact AD disabled / SAP valid and unlocked row; each applies its filter and they combine. | E39: Not set | F39: Not tested | G39: Pending | P39: docs/features/ACCOUNT_REVIEW.md; frontend/tests/account-review-refinement.spec.ts, frontend/tests/investigation-tools.spec.ts | Q39: Not assessed | R39: Unclassified | S39: Not started
A40: AR-003 | B40: Account Review | C40: Account Review › Filters | D40: Finding, license classification and decision filters are multi-select (OR within, AND between) with Saved Filters. | E40: Not set | F40: Not tested | G40: Pending | P40: docs/features/ACCOUNT_REVIEW.md; frontend/tests/investigation-filter-refinement.spec.ts | Q40: Not assessed | R40: Unclassified | S40: Not started
... A44: AR-007 | B44: Account Review | C44: Account Review › Directory unavailable | D44: Without an Employee Directory the page says so, keeps SAP-only review available and does not invent matches. | E44: Not set | F44: Not tested | G44: Pending | P44: docs/features/ACCOUNT_REVIEW.md; frontend/tests/account-review-refinement.spec.ts | Q44: Not assessed | R44: Unclassified | S44: Not started
A45: AR-008 | B45: Account Review | C45: Account Review › Progress and attention layout (R6 correction) | D45: Review progress (about 1/3) and Review attention (about 2/3) share one aligned row without a separate row of five oversized KPI cards; the table starts within the first screen; the investigation notice is an accessible information button; panels stack on narrow screens. | E45: Not set | F45: Not tested | G45: Pending | H45: frontend/tests/account-review-refinement.spec.ts (1/3-2/3 ratio, alignment, icons, right-aligned values, stacking at 375 px, filter combination, keyboard, both themes) | K45: Visually checked in light and dark at 1280 and 375 px (screenshots from frontend/tests/account-review-refinement.spec.ts runs, SHOTS option). | N45: Confirm the layout, density and the information button in both themes. | P45: frontend/src/components/Access/AccountReview.tsx; frontend/src/styles/components.css; docs/features/ACCOUNT_REVIEW.md | Q45: Implemented | R45: Unclassified | S45: Not started
A46: R7-02 | B46: Account Review | C46: Account Review, Review attention › All attention KPI tiles occupy one grid cell | D46: All five Review attention tiles have identical size, padding, radius and states; the fifth sits in the left column and the right cell stays empty; warning colors, neutral zero values and click-to-filter are unchanged. | E46: Not set | F46: Not tested | G46: Pending | H46: frontend/tests/account-review-refinement.spec.ts (equal width and height, no column span, left column, light and dark) | K46: Root cause: a grid-column span on the last tile (review-kpi-secondary). Removed. | N46: Check the panel at desktop and narrow widths in both themes. | P46: frontend/src/components/Access/AccountReview.tsx; frontend/src/styles/components.css | Q46: Implemented | R46: Unclassified | S46: Not started
A47: CMP-001 | B47: Compare Users | C47: Compare users › User selection | D47: Two users can be compared; the same user cannot be on both sides. | E47: Not set | F47: Not tested | G47: Pending | P47: docs/features/COMPARE_USERS.md; frontend/tests/investigation-tools.spec.ts | Q47: Not assessed | R47: Unclassified | S47: Not started
...

Sheet Defects and Findings
A1: ID | B1: Area | C1: Page/component | D1: Priority | E1: Status | F1: Linked issue or finding | G1: Notes | H1: Known limitations
A2: PKG-009 | B2: Access Package | C2: Role Lookup and Release Roles › Floating bars on narrow screens | D2: Low | E2: Needs improvement | G2: Round 4 visual QA at 375 px: the package bar wraps its two buttons onto separate lines and, with the selection bar, stacks to roughly a quarter of the viewport height.
A3: SODR-006 | B3: SoD Reviews | C3: Remediation › Table layout | D3: Low | E3: Needs improvement | G3: Round 3 visual QA: at 1280 px with the filter sidebar open the table scrolls horizontally inside its card, so the Actions column is partly hidden until scrolled. The page itself does not overflow.
A4: UI-016 | B4: Component Library | C4: Components › Info tip trigger size | D4: Low | E4: Needs improvement | G4: Round 4 visual QA: the shared 32 px icon button is taller than headings such as Account review progress.
A5: DEP-005 | B5: Desktop and Startup | C5: Windows › Desktop lifecycle (WebView2) | D5: Not set | E5: Blocked | G5: Not verified in Linux CI: needs a Windows host (see docs/development/TESTING.md, platform limits).
A6: DEP-007 | B6: Desktop and Startup | C6: Windows › Installer | D6: Not set | E6: Blocked | G6: Not verified in Linux CI: needs a Windows host (see docs/development/TESTING.md, platform limits).
A7: DEP-006 | B7: Server and Deployment | C7: Windows › Windows Service | D7: Not set | E7: Blocked | G7: Not verified in Linux CI: needs a Windows host (see docs/development/TESTING.md, platform limits).
A8: DEP-002 | B8: Security and Data Integrity | C8: Runtime › Server mode authentication | D8: Not set | E8: Not tested | F8: SEC-02; SEC-03
A9: SEC-001 | B9: Security and Data Integrity | C9: API › Authentication boundary | D9: High | E9: Not tested | F9: Controls verified (SECURITY_REVIEW_R8) | G9: 122 operations probed in the R8 security review.
A10: SEC-002 | B10: Security and Data Integrity | C10: Exports › Spreadsheet formula neutralisation | D10: Medium | E10: Not tested | F10: SEC-01 (resolved in R8)
A11: SEC-003 | B11: Security and Data Integrity | C11: Server › Access secret and brute-force protection | D11: Medium | E11: Not tested | F11: SEC-02; SEC-03 | G11: No throttling of failed Basic logins; group-readable secret files are accepted (documented limitations). Update R8.1: failed Basic sign-ins are throttled (R81-01) and group-readable secrets need an explicit opt-in (R81-02). | H11: Throttling is per process (see R81-01); distributed guessing relies on the 32 character secret.
A12: SEC-004 | B12: Security and Data Integrity | C12: Server › Source path confinement and uploads | D12: High | E12: Not tested | F12: Controls verified (SECURITY_REVIEW_R8)
A13: SEC-005 | B13: Security and Data Integrity | C13: API › Response headers and content security policy | D13: Low | E13: Not tested | F13: SEC-04
A14: SEC-008 | B14: Security and Data Integrity | C14: Deployment › Container, service and file permissions | D14: High | E14: Not tested | F14: SEC-07 | G14: Static review of Dockerfile, compose.yml and the systemd unit only (R8). Runtime acceptance on systemd, Docker and Windows hosts was not executed. | H14: Not executable on the Linux CI host.
A15: R81-01 | B15: Security and Data Integrity | C15: Server › Failed Basic sign-in throttling | D15: High | E15: Not tested | F15: SEC-02 | G15: Implemented in R8.1 (SEC-02). Automated tests use a fake clock and a TestClient; no real network, proxy or multi-worker deployment was exercised. | H15: State is per process and lost on restart; clients behind one NAT or an unlisted proxy share a lock-out; distributed guessing is slowed, not stopped.
A16: R81-02 | B16: Security and Data Integrity | C16: Server › Access secret file permissions (Linux) | D16: High | E16: Not tested | F16: SEC-03 | G16: Implemented in R8.1 (SEC-03). Judged on the opened file; symlinks resolve to their target. | H16: An existing 0640 secret needs chmod 600 or the opt-in (migration step, documented). Not exercised under real systemd or Docker here.
A17: R81-03 | B17: Server and Deployment | C17: Windows service › Secret file ACL | D17: Medium | E17: Not tested | F17: SEC-03 | G17: Provisioning applies the ACL with icacls (manage-server-service.ps1). Windows ACLs are not evaluated by the Linux tests and not checked at runtime. | H17: Blocked on a Windows host: not run in this validation.
A18: R81-15 | B18: Server and Deployment | C18: Docker and systemd › R8.1 changes | D18: High | E18: Not tested | F18: SEC-07 | G18: The unit passed systemd-analyze verify; it was not booted. Docker was not run. | H18: Blocked here: no real systemd or Docker runtime.

Sheet Future Improvements
A1: ID | B1: Area | C1: Page/component | D1: Priority | E1: Status | F1: Potential future improvement | G1: Notes | H1: Linked issue or finding
A2: PKG-009 | B2: Access Package | C2: Role Lookup and Release Roles › Floating bars on narrow screens | D2: Low | E2: Needs improvement | G2: Round 4 visual QA at 375 px: the package bar wraps its two buttons onto separate lines and, with the selection bar, stacks to roughly a quarter of the viewport height.
A3: SODR-006 | B3: SoD Reviews | C3: Remediation › Table layout | D3: Low | E3: Needs improvement | G3: Round 3 visual QA: at 1280 px with the filter sidebar open the table scrolls horizontally inside its card, so the Actions column is partly hidden until scrolled. The page itself does not overflow.
A4: UI-016 | B4: Component Library | C4: Components › Info tip trigger size | D4: Low | E4: Needs improvement | G4: Round 4 visual QA: the shared 32 px icon button is taller than headings such as Account review progress.
A5: DEP-002 | B5: Security and Data Integrity | C5: Runtime › Server mode authentication | D5: Not set | E5: Not tested | F5: Throttle failed Basic logins and tighten secret-file permissions after a compatibility review (see SEC-003). | H5: SEC-02; SEC-03
A6: SEC-003 | B6: Security and Data Integrity | C6: Server › Access secret and brute-force protection | D6: Medium | E6: Not tested | F6: Share throttle state across workers if the runtime ever scales out. | G6: No throttling of failed Basic logins; group-readable secret files are accepted (documented limitations). Update R8.1: failed Basic sign-ins are throttled (R81-01) and group-readable secrets need an explicit opt-in (R81-02). | H6: SEC-02; SEC-03
A7: SEC-005 | B7: Security and Data Integrity | C7: API › Response headers and content security policy | D7: Low | E7: Not tested | F7: Add a Permissions-Policy header and document HSTS at the TLS-terminating proxy. | H7: SEC-04
A8: SEC-008 | B8: Security and Data Integrity | C8: Deployment › Container, service and file permissions | D8: High | E8: Not tested | F8: Further systemd sandboxing (PrivateDevices, ProtectKernelTunables, RestrictAddressFamilies, SystemCallFilter) after testing under systemd. | G8: Static review of Dockerfile, compose.yml and the systemd unit only (R8). Runtime acceptance on systemd, Docker and Windows hosts was not executed. | H8: SEC-07
A9: R81-01 | B9: Security and Data Integrity | C9: Server › Failed Basic sign-in throttling | D9: High | E9: Not tested | F9: Share counters between workers or hosts, or throttle per forwarded identity at the gateway. | G9: Implemented in R8.1 (SEC-02). Automated tests use a fake clock and a TestClient; no real network, proxy or multi-worker deployment was exercised. | H9: SEC-02
A10: R81-02 | B10: Security and Data Integrity | C10: Server › Access secret file permissions (Linux) | D10: High | E10: Not tested | F10: Verify the owner and effective access through the service account, not only the mode. | G10: Implemented in R8.1 (SEC-03). Judged on the opened file; symlinks resolve to their target. | H10: SEC-03
A11: R81-03 | B11: Server and Deployment | C11: Windows service › Secret file ACL | D11: Medium | E11: Not tested | F11: Check the ACL at start (icacls or the Win32 API) and warn like the POSIX check. | G11: Provisioning applies the ACL with icacls (manage-server-service.ps1). Windows ACLs are not evaluated by the Linux tests and not checked at runtime. | H11: SEC-03
A12: R81-04 | B12: SoD Reports | C12: SoD › Reports › PDF | D12: Medium | E12: Not tested | F12: Show transaction descriptions with their source in the same tables. | G12: Implemented in R8.1. Layout was checked through the model and file validity, not by looking at pages.
